Workbook

Sheet Hypothèses
A1: LÉGENDE : cellules bleues = valeurs modifiables (inputs) — cellules noires = formules.
A2: Scénario HYBRIDE : réseau de prestataires locaux (Toulouse) pour les prestations réactives/légères (U1, U3, U8) — à construire avant le 30/09 — et équipe parisienne pour les productions plus lourdes (U2, U5, U6).
A3: Poste | B3: Valeur | C3: Unité | D3: Source
A4: Réalisateur (pub/institutionnel) | B4: 1200 | C4: €/j | D4: BPU IDFM Grille Coûts Production — SPIAC / Marché pub
A5: Cadreur / JRI (chef opérateur) | B5: 550 | C5: €/j | D5: BPU IDFM Grille Coûts Production — COMETES / Malt
A6: Chef OPS / Ingénieur du son | B6: 500 | C6: €/j | D6: BPU IDFM Grille Coûts Production — COMETES / CCPA
A7: Assistant·e de production (régie) | B7: 300 | C7: €/j | D7: BPU IDFM Grille Coûts Production — COMETES
A8: Monteur·se | B8: 500 | C8: €/j | D8: BPU IDFM Grille Coûts Production — COMETES / Malt
A9: Étalonneur·se | B9: 480 | C9: €/j | D9: BPU IDFM Grille Coûts Production — COMETES / Malt
A10: Mixeur·se | B10: 480 | C10: €/j | D10: BPU IDFM Grille Coûts Production — COMETES / CCPA
A11: Motion designer | B11: 600 | C11: €/j | D11: BPU IDFM Grille Coûts Production — Marché pub / Malt
A12: Storyboarder (freelance) | B12: 400 | C12: €/j | D12: BPU IDFM Grille Coûts Production — Marché pub
A13: Journaliste / accompagnement éditorial | B13: 500 | C13: €/j | D13: BPU IDFM Grille Coûts Production — Concepteur-Rédacteur, Marché/Malt
A14: Taux interne (supervision / coordination) | B14: 200 | C14: €/j | D14: Référentiel de Coûts Internes Pôle Audiovisuel — validé Direction
A15: Cadreur/JRI LOCAL Toulouse (réseau à construire) | B15: 550 | C15: €/j | D15: HYPOTHÈSE — même TJM que Paris faute de données locales, à ajuster une fois le réseau identifié
... A24: TVA | B24: 0.2 | C24: % | D24: Taux standard

Sheet BPU - Grille de prix
A1: Poste | B1: Jours / Quantité | C1: Taux unitaire | D1: Coût
A2: U1 — Interview simple (1/2 journée) — RÉSEAU LOCAL
A3: Cadreur/JRI LOCAL (image + son) | B3: 0.5 | C3: =Hypothèses!$B$15 -> 550 | D3: =B3*C3 -> 275
A4: Supervision interne (coordination à distance) | B4: 0.25 | C4: =Hypothèses!$B$14 -> 200 | D4: =B4*C4 -> 50
A5: Montage (interne, à distance) | B5: 1 | C5: =Hypothèses!$B$8 -> 500 | D5: =B5*C5 -> 500
A6: Kit tournage léger (loué localement) | B6: 0.5 | C6: =Hypothèses!$B$16 -> 300 | D6: =B6*C6 -> 150
A7: Sous-total | D7: =D3+D4+D5+D6 -> 975
A8: Pilotage | C8: =Hypothèses!$B$21 -> 0.05 | D8: =D7*Hypothèses!$B$21 -> 48.75
A9: Assurance production | C9: =Hypothèses!$B$22 -> 0.03 | D9: =D7*Hypothèses!$B$22 -> 29.25
A10: Provision imprévus | C10: =Hypothèses!$B$23 -> 0.05 | D10: =D7*Hypothèses!$B$23 -> 48.75
A11: PRIX UNITAIRE (HT) | D11: =D7+D8+D9+D10 -> 1101.75
A12: TVA | D12: =D11*Hypothèses!$B$24 -> 220.35
A13: PRIX UNITAIRE (TTC) | D13: =D11+D12 -> 1322.1
A15: U2 — Portrait / témoignage (1 jour) — équipe Paris
A16: Réalisateur (direction, mi-temps) | B16: 0.5 | C16: =Hypothèses!$B$4 -> 1200 | D16: =B16*C16 -> 600
A17: Cadreur / JRI | B17: 1 | C17: =Hypothèses!$B$5 -> 550 | D17: =B17*C17 -> 550
A18: Chef OPS / Ingénieur du son | B18: 1 | C18: =Hypothèses!$B$6 -> 500 | D18: =B18*C18 -> 500
A19: Régie | B19: 0.5 | C19: =Hypothèses!$B$7 -> 300 | D19: =B19*C19 -> 150
A20: Supervision interne | B20: 0.25 | C20: =Hypothèses!$B$14 -> 200 | D20: =B20*C20 -> 50
A21: Montage | B21: 1.5 | C21: =Hypothèses!$B$8 -> 500 | D21: =B21*C21 -> 750
A22: Étalonnage | B22: 0.25 | C22: =Hypothèses!$B$9 -> 480 | D22: =B22*C22 -> 120
A23: Déplacement Paris-Toulouse (équipe légère) | B23: 1 | C23: =Hypothèses!$B$18 -> 900 | D23: =B23*C23 -> 900
A24: Kit tournage intermédiaire | B24: 1 | C24: =Hypothèses!$B$17 -> 700 | D24: =B24*C24 -> 700
A25: Sous-total | D25: =D16+D17+D18+D19+D20+D21+D22+D23+D24 -> 4320
A26: Pilotage | C26: =Hypothèses!$B$21 -> 0.05 | D26: =D25*Hypothèses!$B$21 -> 216
A27: Assurance production | C27: =Hypothèses!$B$22 -> 0.03 | D27: =D25*Hypothèses!$B$22 -> 129.6
A28: Provision imprévus | C28: =Hypothèses!$B$23 -> 0.05 | D28: =D25*Hypothèses!$B$23 -> 216
A29: PRIX UNITAIRE (HT) | D29: =D25+D26+D27+D28 -> 4881.6
A30: TVA | D30: =D29*Hypothèses!$B$24 -> 976.32
A31: PRIX UNITAIRE (TTC) | D31: =D29+D30 -> 5857.92
A33: U3 — Reportage événementiel (1 jour) — RÉSEAU LOCAL
A34: Cadreur/JRI LOCAL | B34: 1 | C34: =Hypothèses!$B$15 -> 550 | D34: =B34*C34 -> 550
A35: Supervision interne (coordination à distance) | B35: 0.25 | C35: =Hypothèses!$B$14 -> 200 | D35: =B35*C35 -> 50
A36: Montage (interne, à distance) | B36: 1.5 | C36: =Hypothèses!$B$8 -> 500 | D36: =B36*C36 -> 750
A37: Kit tournage intermédiaire (loué localement) | B37: 1 | C37: =Hypothèses!$B$17 -> 700 | D37: =B37*C37 -> 700
A38: Sous-total | D38: =D34+D35+D36+D37 -> 2050
A39: Pilotage | C39: =Hypothèses!$B$21 -> 0.05 | D39: =D38*Hypothèses!$B$21 -> 102.5
A40: Assurance production | C40: =Hypothèses!$B$22 -> 0.03 | D40: =D38*Hypothèses!$B$22 -> 61.5
A41: Provision imprévus | C41: =Hypothèses!$B$23 -> 0.05 | D41: =D38*Hypothèses!$B$23 -> 102.5
A42: PRIX UNITAIRE (HT) | D42: =D38+D39+D40+D41 -> 2316.5
...

Sheet Récapitulatif DQE
A1: Unité | B1: Prix unitaire HT | C1: Prix unitaire TTC | D1: Équipe
A2: U1 — Interview simple (1/2 journée) — RÉSEAU LOCAL | B2: ='BPU - Grille de prix'!D11 -> 1101.75 | C2: ='BPU - Grille de prix'!D13 -> 1322.1 | D2: Locale (à construire)
A3: U2 — Portrait / témoignage (1 jour) — équipe Paris | B3: ='BPU - Grille de prix'!D29 -> 4881.6 | C3: ='BPU - Grille de prix'!D31 -> 5857.92 | D3: Paris
A4: U3 — Reportage événementiel (1 jour) — RÉSEAU LOCAL | B4: ='BPU - Grille de prix'!D42 -> 2316.5 | C4: ='BPU - Grille de prix'!D44 -> 2779.8 | D4: Locale (à construire)
A5: U4 — Capsule réseaux sociaux (déclinaison, sans tournage) | B5: ='BPU - Grille de prix'!D50 -> 262.5 | C5: ='BPU - Grille de prix'!D52 -> 315 | D5: Paris
A6: U5 — Film institutionnel (2 jours de tournage) — équipe Paris | B6: ='BPU - Grille de prix'!D72 -> 12407.4 | C6: ='BPU - Grille de prix'!D74 -> 14888.88 | D6: Paris
A7: U6 — Vidéo vulgarisation scientifique (1,5 jour) — équipe Paris | B7: ='BPU - Grille de prix'!D90 -> 7034.25 | C7: ='BPU - Grille de prix'!D92 -> 8441.1 | D7: Paris
A8: U7 — Sous-titrage additionnel (par vidéo) | B8: ='BPU - Grille de prix'!D98 -> 131.25 | C8: ='BPU - Grille de prix'!D100 -> 157.5 | D8: Paris
A9: U8 — Prestation urgente 48h (1/2 journée) — RÉSEAU LOCAL | B9: ='BPU - Grille de prix'!D112 -> 1299.5 | C9: ='BPU - Grille de prix'!D114 -> 1559.4 | D9: Locale (à construire)
A11: Scénario hybride : U1/U3/U8 supposent un réseau de prestataires toulousains identifié avant le 30/09 — sinon, reprendre les prix 'équipe Paris' du chiffrage précédent pour ces 3 unités.
